<?xml version="1.0" encoding="UTF-8"?>
<testng-results skipped="0" failed="1" ignored="0" total="1" passed="0">
  <reporter-output>
  </reporter-output>
<<<<<<< HEAD
  <suite name="Suite" duration-ms="95" started-at="2017-12-13T04:24:29Z" finished-at="2017-12-13T04:24:29Z">
    <groups>
    </groups>
    <test name="Test" duration-ms="95" started-at="2017-12-13T04:24:29Z" finished-at="2017-12-13T04:24:29Z">
      <class name="ez.testcases.finsys.ValidLogin_01">
        <test-method status="FAIL" signature="ValidLogin()[pri:0, instance:ez.testcases.finsys.ValidLogin_01@27efef64]" name="ValidLogin" duration-ms="21" started-at="2017-12-13T09:54:29Z" finished-at="2017-12-13T09:54:29Z">
          <exception class="java.lang.NullPointerException">
            <full-stacktrace>
              <![CDATA[java.lang.NullPointerException
	at ez.testcases.finsys.ValidLogin_01.ValidLogin(ValidLogin_01.java:16)
=======
  <suite name="Suite" duration-ms="67" started-at="2017-12-13T14:40:45Z" finished-at="2017-12-13T14:40:45Z">
    <groups>
    </groups>
    <test name="Test" duration-ms="67" started-at="2017-12-13T14:40:45Z" finished-at="2017-12-13T14:40:45Z">
      <class name="ez.testcases.finsys.ValidLogin_01">
        <test-method status="FAIL" signature="ValidLogin()[pri:0, instance:ez.testcases.finsys.ValidLogin_01@8bd1b6a]" name="ValidLogin" duration-ms="12" started-at="2017-12-13T20:10:45Z" finished-at="2017-12-13T20:10:45Z">
          <exception class="java.lang.NullPointerException">
            <full-stacktrace>
              <![CDATA[java.lang.NullPointerException
	at ez.testcases.finsys.ValidLogin_01.ValidLogin(ValidLogin_01.java:14)
>>>>>>> edb7a53aeb96957b91fac04155131b68d98e0944
	at sun.reflect.NativeMethodAccessorImpl.invoke0(Native Method)
	at sun.reflect.NativeMethodAccessorImpl.invoke(Unknown Source)
	at sun.reflect.DelegatingMethodAccessorImpl.invoke(Unknown Source)
	at java.lang.reflect.Method.invoke(Unknown Source)
	at org.testng.internal.MethodInvocationHelper.invokeMethod(MethodInvocationHelper.java:108)
	at org.testng.internal.Invoker.invokeMethod(Invoker.java:661)
	at org.testng.internal.Invoker.invokeTestMethod(Invoker.java:869)
	at org.testng.internal.Invoker.invokeTestMethods(Invoker.java:1193)
	at org.testng.internal.TestMethodWorker.invokeTestMethods(TestMethodWorker.java:126)
	at org.testng.internal.TestMethodWorker.run(TestMethodWorker.java:109)
	at org.testng.TestRunner.privateRun(TestRunner.java:744)
	at org.testng.TestRunner.run(TestRunner.java:602)
	at org.testng.SuiteRunner.runTest(SuiteRunner.java:380)
	at org.testng.SuiteRunner.runSequentially(SuiteRunner.java:375)
	at org.testng.SuiteRunner.privateRun(SuiteRunner.java:340)
	at org.testng.SuiteRunner.run(SuiteRunner.java:289)
	at org.testng.SuiteRunnerWorker.runSuite(SuiteRunnerWorker.java:52)
	at org.testng.SuiteRunnerWorker.run(SuiteRunnerWorker.java:86)
	at org.testng.TestNG.runSuitesSequentially(TestNG.java:1301)
	at org.testng.TestNG.runSuitesLocally(TestNG.java:1226)
	at org.testng.TestNG.runSuites(TestNG.java:1144)
	at org.testng.TestNG.run(TestNG.java:1115)
	at org.testng.remote.AbstractRemoteTestNG.run(AbstractRemoteTestNG.java:114)
	at org.testng.remote.RemoteTestNG.initAndRun(RemoteTestNG.java:251)
	at org.testng.remote.RemoteTestNG.main(RemoteTestNG.java:77)
]]>
            </full-stacktrace>
          </exception> <!-- java.lang.NullPointerException -->
          <reporter-output>
          </reporter-output>
        </test-method> <!-- ValidLogin -->
      </class> <!-- ez.testcases.finsys.ValidLogin_01 -->
    </test> <!-- Test -->
  </suite> <!-- Suite -->
</testng-results>
